Workbook

Sheet Inventario
A1: Inventario de activos de ciudad · Imbornales de Ciudad Juan Bosch
A2: Fuente: levantamiento de Verasol (27/07/2026) · Coordenadas UTM 19N (WGS 84) · FIDEICOMISO PARA LA CONSTRUCCIÓN DE VIVIENDAS DE BAJO COSTO (FIDEICOMISO VBC RD)
A4: 473 imbornales · un clic en «Ver ↗» abre el punto en Google Maps · las observaciones señalan datos a confirmar con Verasol
A5: ID | B5: Tipo | C5: Ubicación | D5: Calle | E5: Lote donde está | F5: Nombre del lote | G5: Lote más cercano | H5: Distancia al lote (m) | I5: Cota (m) | J5: UTM Este | K5: UTM Norte | L5: Latitud | M5: Longitud | N5: No. en levantamiento | O5: Tipo anotado | P5: Observaciones | Q5: Mapa
A6: IMB-001 | B6: Filtrante doble | C6: Calle | D6: Calle Prof. Juan Bosch | G6: 09-32-03 | H6: 3.1 | I6: 34.533 | J6: 420573.96 | K6: 2043946.9 | L6: 18.484423 | M6: -69.752338 | N6: 1 | O6: filtrante doble | Q6: Ver ↗
A7: IMB-002 | B7: Filtrante doble | C7: Calle | D7: Calle Prof. Juan Bosch | G7: 09-32-03 | H7: 17.4 | I7: 34.534 | J7: 420574.9 | K7: 2043932.6 | L7: 18.484294 | M7: -69.752329 | N7: 2 | O7: filtrante doble | Q7: Ver ↗
A8: IMB-003 | B8: Filtrante doble | C8: Calle | D8: Calle Prof. Juan Bosch | G8: 09-32-03 | H8: 17.6 | I8: 34.311 | J8: 420718.84 | K8: 2043939 | L8: 18.484357 | M8: -69.750966 | N8: 3 | O8: filtrante doble | Q8: Ver ↗
A9: IMB-004 | B9: Filtrante doble | C9: Dentro de lote | E9: 09-32-03 | F9: Centro de Atención Primaria | G9: 09-32-03 | H9: 0 | I9: 34.17 | J9: 420718.8 | K9: 2043957.6 | L9: 18.484525 | M9: -69.750967 | N9: 4 | O9: filtrante doble | Q9: Ver ↗
A10: IMB-005 | B10: Filtrante doble | C10: Calle | D10: Calle Prof. Juan Bosch | G10: 07-35-02 | H10: 16.9 | I10: 32.615 | J10: 421181.27 | K10: 2043961.5 | L10: 18.484578 | M10: -69.746587 | N10: 5 | O10: filtrante doble | Q10: Ver ↗
A11: IMB-006 | B11: Filtrante doble | C11: Calle | D11: Calle Prof. Juan Bosch | G11: 07-35-02 | H11: 2.5 | I11: 32.608 | J11: 421180.62 | K11: 2043975.9 | L11: 18.484707 | M11: -69.746593 | N11: 6 | O11: filtrante doble | Q11: Ver ↗
A12: IMB-007 | B12: Filtrante doble | C12: Calle | D12: Avenida El Sembrador | G12: 07-31-06 | H12: 33 | I12: 32.485 | J12: 421582.74 | K12: 2044070 | L12: 18.485574 | M12: -69.742788 | N12: 7 | O12: filtrante doble | Q12: Ver ↗
A13: IMB-008 | B13: Filtrante simple | C13: Calle | D13: Avenida El Sembrador | G13: 07-35-06 | H13: 27.9 | I13: 32.89 | J13: 421583.51 | K13: 2044029.8 | L13: 18.48521 | M13: -69.742779 | N13: 8 | O13: filtrante | Q13: Ver ↗
A14: IMB-009 | B14: Filtrante simple | C14: Calle | D14: Avenida El Sembrador | G14: 07-31-06 | H14: 28 | I14: 32.835 | J14: 421581.74 | K14: 2044120.2 | L14: 18.486027 | M14: -69.7428 | N14: 9 | O14: filtrante | Q14: Ver ↗
A15: IMB-010 | B15: Filtrante simple | C15: Calle | D15: Avenida El Sembrador | G15: 07-31-02 | H15: 28 | I15: 33.768 | J15: 421578.86 | K15: 2044260.2 | L15: 18.487292 | M15: -69.742833 | N15: 10 | O15: filtrante | Q15: Ver ↗
A16: IMB-011 | B16: Filtrante simple | C16: Calle | D16: Avenida El Sembrador | G16: 06-26-01 | H16: 28 | I16: 34.087 | J16: 421572.64 | K16: 2044560.3 | L16: 18.490004 | M16: -69.742903 | N16: 11 | O16: filtrante | Q16: Ver ↗
A17: IMB-012 | B17: Filtrante doble | C17: Calle | D17: Avenida El Sembrador | G17: 06-26-01 | H17: 28 | I17: 33.651 | J17: 421570.82 | K17: 2044647.1 | L17: 18.490789 | M17: -69.742924 | N17: 12 | O17: filtrante doble | Q17: Ver ↗
A18: IMB-013 | B18: Filtrante simple | C18: Calle | D18: Avenida El Sembrador | G18: 06-26-01 | H18: 20.7 | I18: 33.837 | J18: 421563.58 | K18: 2044646 | L18: 18.490778 | M18: -69.742992 | N18: 13 | O18: filtrante | Q18: Ver ↗
A19: IMB-014 | B19: Filtrante doble | C19: Calle | D19: Avenida El Sembrador | G19: 04-40-02 | H19: 4.3 | I19: 32.529 | J19: 421561.62 | K19: 2045094.5 | L19: 18.494831 | M19: -69.743028 | N19: 14 | O19: filtrante doble | Q19: Ver ↗
A20: IMB-015 | B20: Filtrante simple | C20: Calle | D20: Avenida El Sembrador | G20: 04-39-01 | H20: 4.3 | I20: 31.59 | J20: 421589.02 | K20: 2045401.1 | L20: 18.497603 | M20: -69.742781 | N20: 15 | O20: filtrante | Q20: Ver ↗
A21: IMB-016 | B21: Filtrante simple | C21: Calle | D21: Avenida El Sembrador | G21: 04-39-01 | H21: 4.4 | I21: 30.736 | J21: 421639.3 | K21: 2045502.4 | L21: 18.498521 | M21: -69.742308 | N21: 16 | O21: filtrante | Q21: Ver ↗
... A35: IMB-030 | B35: Filtrante simple | C35: Calle | D35: Avenida El Sembrador | G35: 01-01-03 | H35: 3.6 | I35: 24.085 | J35: 421515.96 | K35: 2047073.5 | L35: 18.512715 | M35: -69.743538 | N35: 30 | O35: filtrante | Q35: Ver ↗
A36: IMB-031 | B36: Filtrante simple | C36: Calle | D36: Avenida El Sembrador | G36: 01-01-03 | H36: 3.5 | I36: 23.508 | J36: 421483.39 | K36: 2047133.3 | L36: 18.513254 | M36: -69.743849 | N36: 31 | O36: filtrante | P36: Misma coordenada que IMB-032: posible registro duplicado. | Q36: Ver ↗
A37: IMB-032 | B37: Filtrante simple | C37: Calle | D37: Avenida El Sembrador | G37: 01-01-03 | H37: 3.5 | I37: 23.512 | J37: 421483.39 | K37: 2047133.3 | L37: 18.513254 | M37: -69.743849 | N37: 32 | O37: filtrante | P37: Misma coordenada que IMB-031: posible registro duplicado. | Q37: Ver ↗
A38: IMB-033 | B38: Filtrante simple | C38: Calle | D38: Avenida El Sembrador | G38: 01-01-02 | H38: 4 | I38: 22.835 | J38: 421461.07 | K38: 2047200.2 | L38: 18.513857 | M38: -69.744063 | N38: 33 | O38: filtrante | Q38: Ver ↗
A39: IMB-034 | B39: Filtrante simple | C39: Calle | D39: Avenida El Sembrador | G39: 01-02-01 | H39: 2.6 | I39: 23.679 | J39: 421454.13 | K39: 2047118.2 | L39: 18.513116 | M39: -69.744125 | N39: 34 | O39: filtrante | Q39: Ver ↗
A40: IMB-035 | B40: Filtrante simple | C40: Calle | D40: Avenida El Sembrador | G40: 01-02-04 | H40: 2.7 | I40: 23.908 | J40: 421490.16 | K40: 2047052.5 | L40: 18.512523 | M40: -69.743782 | N40: 35 | O40: filtrante | Q40: Ver ↗
A41: IMB-036 | B41: Filtrante doble | C41: Calle | D41: Avenida El Sembrador | G41: 01-02-04 | H41: 2.8 | I41: 23.82 | J41: 421578.7 | K41: 2046891.3 | L41: 18.51107 | M41: -69.742936 | N41: 36 | O41: filtrante doble | Q41: Ver ↗
A42: IMB-037 | B42: Filtrante simple | C42: Calle | D42: Calle la muchacha de la Guaira | G42: 01-02-05 | H42: 8.2 | I42: 25.009 | J42: 421697.32 | K42: 2046668.3 | L42: 18.50906 | M42: -69.741804 | N42: 37 | O42: filtrante | Q42: Ver ↗
A43: IMB-038 | B43: Filtrante doble | C43: Calle | D43: Avenida El Sembrador | G43: 01-03-01 | H43: 2.6 | I43: 24.507 | J43: 421766.53 | K43: 2046548.6 | L43: 18.50798 | M43: -69.741144 | N43: 38 | O43: filtrante doble | Q43: Ver ↗
A44: IMB-039 | B44: Filtrante simple | C44: Calle | D44: Avenida El Sembrador | G44: 01-03-01 | H44: 2.5 | I44: 25.715 | J44: 421832.11 | K44: 2046428.7 | L44: 18.506899 | M44: -69.740518 | N44: 39 | O44: filtrante | Q44: Ver ↗
A45: IMB-040 | B45: Filtrante simple | C45: Calle | D45: Avenida El Sembrador | G45: 04-11-05 | H45: 3.6 | I45: 28.892 | J45: 421915.25 | K45: 2046252.4 | L45: 18.505309 | M45: -69.739723 | N45: 40 | O45: filtrante | Q45: Ver ↗
A46: IMB-041 | B46: Filtrante doble | C46: Calle | D46: Avenida El Sembrador | G46: 04-11-03 | H46: 1.7 | I46: 27.705 | J46: 421878.46 | K46: 2046040.5 | L46: 18.503392 | M46: -69.740064 | N46: 41 | O46: filtrante doble | Q46: Ver ↗
A47: IMB-042 | B47: Filtrante simple | C47: Calle | D47: Avenida El Sembrador | G47: 04-15-01 | H47: 0.8 | I47: 28.591 | J47: 421803.12 | K47: 2045889.1 | L47: 18.502021 | M47: -69.740772 | N47: 42 | O47: filtrante | Q47: Ver ↗
A48: IMB-043 | B48: Filtrante simple | C48: Calle | D48: Avenida El Sembrador | G48: 04-15-01 | H48: 0.8 | I48: 29.559 | J48: 421720.61 | K48: 2045723.4 | L48: 18.500521 | M48: -69.741547 | N48: 43 | O48: filtrante | Q48: Ver ↗
A49: IMB-044 | B49: Filtrante simple | C49: Calle | D49: Avenida El Sembrador | G49: 04-16-01 | H49: 1.6 | I49: 30.873 | J49: 421616.13 | K49: 2045514.2 | L49: 18.498626 | M49: -69.742528 | N49: 44 | O49: filtrante | Q49: Ver ↗
... A171: IMB-166 | B171: Filtrante doble | C171: Calle | D171: Avenida La Gaviota Tramo 1 | G171: 08-23-01 | H171: 6 | I171: 33.377 | J171: 420741.72 | K171: 2044780.5 | L171: 18.491963 | M171: -69.750782 | N171: 166 | O171: filtrante doble | Q171: Ver ↗
A172: IMB-167 | B172: Filtrante tipo «A» (por confirmar) | C172: Calle | D172: Avenida La Gaviota Tramo 1 | G172: 08-22-04 | H172: 1.4 | I172: 33.638 | J172: 420728.48 | K172: 2044735.2 | L172: 18.491553 | M172: -69.750906 | N172: 167 | O172: filtrante a | P172: Tipo «filtrante a» sin definición: confirmar con Verasol. | Q172: Ver ↗
A173: IMB-168 | B173: Filtrante tipo «A» (por confirmar) | C173: Calle | D173: Avenida La Gaviota Tramo 1 | G173: 08-23-01 | H173: 5.9 | I173: 33.761 | J173: 420744.06 | K173: 2044733.5 | L173: 18.491538 | M173: -69.750758 | N173: 168 | O173: filtrante a | P173: Tipo «filtrante a» sin definición: confirmar con Verasol. | Q173: Ver ↗
A174: IMB-169 | B174: Filtrante tipo «A» (por confirmar) | C174: Calle | D174: Avenida La Gaviota Tramo 1 | G174: 08-23-01 | H174: 5.8 | I174: 34.059 | J174: 420745.76 | K174: 2044700 | L174: 18.491236 | M174: -69.750741 | N174: 169 | O174: filtrante a | P174: Tipo «filtrante a» sin definición: confirmar con Verasol. | Q174: Ver ↗
A175: IMB-170 | B175: Filtrante tipo «A» (por confirmar) | C175: Calle | D175: Avenida La Gaviota Tramo 1 | G175: 08-22-04 | H175: 1.4 | I175: 33.949 | J175: 420730.22 | K175: 2044698.5 | L175: 18.491221 | M175: -69.750888 | N175: 170 | O175: filtrante a | P175: Tipo «filtrante a» sin definición: confirmar con Verasol. | Q175: Ver ↗
...

Sheet Resumen por calle
A1: Resumen por calle
A2: Se calcula con fórmulas a partir de la hoja Inventario
A5: Calle / ubicación | B5: Filtrante simple | C5: Filtrante doble | D5: Filtrante tipo «A» (por confirmar) | E5: Cisterna (PG) | F5: Total
A6: Avenida La Gaviota Tramo 1 | B6: =COUNTIFS(Inventario!$D$6:$D$478,$A6,Inventario!$B$6:$B$478,"Filtrante simple") -> 48 | C6: =COUNTIFS(Inventario!$D$6:$D$478,$A6,Inventario!$B$6:$B$478,"Filtrante doble") -> 12 | D6: =COUNTIFS(Inventario!$D$6:$D$478,$A6,Inventario!$B$6:$B$478,"Filtrante tipo «A» (por confirmar)") -> 5 | E6: =COUNTIFS(Inventario!$D$6:$D$478,$A6,Inventario!$B$6:$B$478,"Cisterna (PG)") -> 0 | F6: =SUM(B6:E6) -> 65
A7: Avenida El Sembrador | B7: =COUNTIFS(Inventario!$D$6:$D$478,$A7,Inventario!$B$6:$B$478,"Filtrante simple") -> 45 | C7: =COUNTIFS(Inventario!$D$6:$D$478,$A7,Inventario!$B$6:$B$478,"Filtrante doble") -> 10 | D7: =COUNTIFS(Inventario!$D$6:$D$478,$A7,Inventario!$B$6:$B$478,"Filtrante tipo «A» (por confirmar)") -> 0 | E7: =COUNTIFS(Inventario!$D$6:$D$478,$A7,Inventario!$B$6:$B$478,"Cisterna (PG)") -> 0 | F7: =SUM(B7:E7) -> 55
A8: Avenida Camino Real Nor Este | B8: =COUNTIFS(Inventario!$D$6:$D$478,$A8,Inventario!$B$6:$B$478,"Filtrante simple") -> 43 | C8: =COUNTIFS(Inventario!$D$6:$D$478,$A8,Inventario!$B$6:$B$478,"Filtrante doble") -> 11 | D8: =COUNTIFS(Inventario!$D$6:$D$478,$A8,Inventario!$B$6:$B$478,"Filtrante tipo «A» (por confirmar)") -> 0 | E8: =COUNTIFS(Inventario!$D$6:$D$478,$A8,Inventario!$B$6:$B$478,"Cisterna (PG)") -> 0 | F8: =SUM(B8:E8) -> 54
A9: Boulevard el Oro y la Paz | B9: =COUNTIFS(Inventario!$D$6:$D$478,$A9,Inventario!$B$6:$B$478,"Filtrante simple") -> 26 | C9: =COUNTIFS(Inventario!$D$6:$D$478,$A9,Inventario!$B$6:$B$478,"Filtrante doble") -> 5 | D9: =COUNTIFS(Inventario!$D$6:$D$478,$A9,Inventario!$B$6:$B$478,"Filtrante tipo «A» (por confirmar)") -> 0 | E9: =COUNTIFS(Inventario!$D$6:$D$478,$A9,Inventario!$B$6:$B$478,"Cisterna (PG)") -> 0 | F9: =SUM(B9:E9) -> 31
A10: Boulevard La Mujer | B10: =COUNTIFS(Inventario!$D$6:$D$478,$A10,Inventario!$B$6:$B$478,"Filtrante simple") -> 25 | C10: =COUNTIFS(Inventario!$D$6:$D$478,$A10,Inventario!$B$6:$B$478,"Filtrante doble") -> 4 | D10: =COUNTIFS(Inventario!$D$6:$D$478,$A10,Inventario!$B$6:$B$478,"Filtrante tipo «A» (por confirmar)") -> 0 | E10: =COUNTIFS(Inventario!$D$6:$D$478,$A10,Inventario!$B$6:$B$478,"Cisterna (PG)") -> 0 | F10: =SUM(B10:E10) -> 29
A11: Calle Encarnacion Mendoza | B11: =COUNTIFS(Inventario!$D$6:$D$478,$A11,Inventario!$B$6:$B$478,"Filtrante simple") -> 16 | C11: =COUNTIFS(Inventario!$D$6:$D$478,$A11,Inventario!$B$6:$B$478,"Filtrante doble") -> 8 | D11: =COUNTIFS(Inventario!$D$6:$D$478,$A11,Inventario!$B$6:$B$478,"Filtrante tipo «A» (por confirmar)") -> 0 | E11: =COUNTIFS(Inventario!$D$6:$D$478,$A11,Inventario!$B$6:$B$478,"Cisterna (PG)") -> 0 | F11: =SUM(B11:E11) -> 24
A12: Calle Rey David | B12: =COUNTIFS(Inventario!$D$6:$D$478,$A12,Inventario!$B$6:$B$478,"Filtrante simple") -> 20 | C12: =COUNTIFS(Inventario!$D$6:$D$478,$A12,Inventario!$B$6:$B$478,"Filtrante doble") -> 3 | D12: =COUNTIFS(Inventario!$D$6:$D$478,$A12,Inventario!$B$6:$B$478,"Filtrante tipo «A» (por confirmar)") -> 0 | E12: =COUNTIFS(Inventario!$D$6:$D$478,$A12,Inventario!$B$6:$B$478,"Cisterna (PG)") -> 0 | F12: =SUM(B12:E12) -> 23
A13: Calle Papa Juan | B13: =COUNTIFS(Inventario!$D$6:$D$478,$A13,Inventario!$B$6:$B$478,"Filtrante simple") -> 14 | C13: =COUNTIFS(Inventario!$D$6:$D$478,$A13,Inventario!$B$6:$B$478,"Filtrante doble") -> 5 | D13: =COUNTIFS(Inventario!$D$6:$D$478,$A13,Inventario!$B$6:$B$478,"Filtrante tipo «A» (por confirmar)") -> 0 | E13: =COUNTIFS(Inventario!$D$6:$D$478,$A13,Inventario!$B$6:$B$478,"Cisterna (PG)") -> 0 | F13: =SUM(B13:E13) -> 19
A14: Calle Carmen Quidiello De Bosch | B14: =COUNTIFS(Inventario!$D$6:$D$478,$A14,Inventario!$B$6:$B$478,"Filtrante simple") -> 17 | C14: =COUNTIFS(Inventario!$D$6:$D$478,$A14,Inventario!$B$6:$B$478,"Filtrante doble") -> 1 | D14: =COUNTIFS(Inventario!$D$6:$D$478,$A14,Inventario!$B$6:$B$478,"Filtrante tipo «A» (por confirmar)") -> 0 | E14: =COUNTIFS(Inventario!$D$6:$D$478,$A14,Inventario!$B$6:$B$478,"Cisterna (PG)") -> 0 | F14: =SUM(B14:E14) -> 18
A15: Calle Fragata | B15: =COUNTIFS(Inventario!$D$6:$D$478,$A15,Inventario!$B$6:$B$478,"Filtrante simple") -> 11 | C15: =COUNTIFS(Inventario!$D$6:$D$478,$A15,Inventario!$B$6:$B$478,"Filtrante doble") -> 5 | D15: =COUNTIFS(Inventario!$D$6:$D$478,$A15,Inventario!$B$6:$B$478,"Filtrante tipo «A» (por confirmar)") -> 0 | E15: =COUNTIFS(Inventario!$D$6:$D$478,$A15,Inventario!$B$6:$B$478,"Cisterna (PG)") -> 0 | F15: =SUM(B15:E15) -> 16
A16: Calle la muchacha de la Guaira | B16: =COUNTIFS(Inventario!$D$6:$D$478,$A16,Inventario!$B$6:$B$478,"Filtrante simple") -> 11 | C16: =COUNTIFS(Inventario!$D$6:$D$478,$A16,Inventario!$B$6:$B$478,"Filtrante doble") -> 2 | D16: =COUNTIFS(Inventario!$D$6:$D$478,$A16,Inventario!$B$6:$B$478,"Filtrante tipo «A» (por confirmar)") -> 0 | E16: =COUNTIFS(Inventario!$D$6:$D$478,$A16,Inventario!$B$6:$B$478,"Cisterna (PG)") -> 0 | F16: =SUM(B16:E16) -> 13
A17: Calle Dos Amigos | B17: =COUNTIFS(Inventario!$D$6:$D$478,$A17,Inventario!$B$6:$B$478,"Filtrante simple") -> 13 | C17: =COUNTIFS(Inventario!$D$6:$D$478,$A17,Inventario!$B$6:$B$478,"Filtrante doble") -> 0 | D17: =COUNTIFS(Inventario!$D$6:$D$478,$A17,Inventario!$B$6:$B$478,"Filtrante tipo «A» (por confirmar)") -> 0 | E17: =COUNTIFS(Inventario!$D$6:$D$478,$A17,Inventario!$B$6:$B$478,"Cisterna (PG)") -> 0 | F17: =SUM(B17:E17) -> 13
... A32: Paseo Rio Verde | B32: =COUNTIFS(Inventario!$D$6:$D$478,$A32,Inventario!$B$6:$B$478,"Filtrante simple") -> 2 | C32: =COUNTIFS(Inventario!$D$6:$D$478,$A32,Inventario!$B$6:$B$478,"Filtrante doble") -> 0 | D32: =COUNTIFS(Inventario!$D$6:$D$478,$A32,Inventario!$B$6:$B$478,"Filtrante tipo «A» (por confirmar)") -> 0 | E32: =COUNTIFS(Inventario!$D$6:$D$478,$A32,Inventario!$B$6:$B$478,"Cisterna (PG)") -> 0 | F32: =SUM(B32:E32) -> 2
A33: Dentro de lote | B33: =COUNTIFS(Inventario!$C$6:$C$478,$A33,Inventario!$B$6:$B$478,"Filtrante simple") -> 14 | C33: =COUNTIFS(Inventario!$C$6:$C$478,$A33,Inventario!$B$6:$B$478,"Filtrante doble") -> 3 | D33: =COUNTIFS(Inventario!$C$6:$C$478,$A33,Inventario!$B$6:$B$478,"Filtrante tipo «A» (por confirmar)") -> 0 | E33: =COUNTIFS(Inventario!$C$6:$C$478,$A33,Inventario!$B$6:$B$478,"Cisterna (PG)") -> 1 | F33: =SUM(B33:E33) -> 18
A34: Fuera de lotes del Master Plan | B34: =COUNTIFS(Inventario!$C$6:$C$478,$A34,Inventario!$B$6:$B$478,"Filtrante simple") -> 1 | C34: =COUNTIFS(Inventario!$C$6:$C$478,$A34,Inventario!$B$6:$B$478,"Filtrante doble") -> 0 | D34: =COUNTIFS(Inventario!$C$6:$C$478,$A34,Inventario!$B$6:$B$478,"Filtrante tipo «A» (por confirmar)") -> 0 | E34: =COUNTIFS(Inventario!$C$6:$C$478,$A34,Inventario!$B$6:$B$478,"Cisterna (PG)") -> 0 | F34: =SUM(B34:E34) -> 1
A35: Total | B35: =SUM(B6:B34) -> 365 | C35: =SUM(C6:C34) -> 102 | D35: =SUM(D6:D34) -> 5 | E35: =SUM(E6:E34) -> 1 | F35: =SUM(F6:F34) -> 473

Sheet Por revisar con Verasol
A1: Datos a confirmar con Verasol
A2: Diferencias encontradas al procesar el levantamiento; ninguna impide usar el inventario
A5: ID | B5: Fila en el Excel original | C5: Situación | D5: Coordenada (UTM E / N)
A6: IMB-031 | B6: 445 | C6: Misma coordenada que IMB-032: posible registro duplicado. | D6: 421483.39 / 2047133.27
A7: IMB-032 | B7: 444 | C7: Misma coordenada que IMB-031: posible registro duplicado. | D7: 421483.39 / 2047133.27
A8: IMB-167 | B8: 309 | C8: Tipo «filtrante a» sin definición: confirmar con Verasol. | D8: 420728.48 / 2044735.17
A9: IMB-168 | B9: 308 | C9: Tipo «filtrante a» sin definición: confirmar con Verasol. | D9: 420744.06 / 2044733.49
A10: IMB-169 | B10: 307 | C10: Tipo «filtrante a» sin definición: confirmar con Verasol. | D10: 420745.76 / 2044700.04
A11: IMB-170 | B11: 306 | C11: Tipo «filtrante a» sin definición: confirmar con Verasol. | D11: 420730.22 / 2044698.50
A12: IMB-171 | B12: 305 | C12: Tipo «filtrante a» sin definición: confirmar con Verasol. | D12: 420732.03 / 2044663.92
A13: IMB-220 | B13: 255 | C13: Tipo escrito «filtrantedoble»; se asumió filtrante doble. | D13: 420584.49 / 2044399.68
A14: IMB-238 | B14: 237 | C14: Tipo escrito «filtrant» en el levantamiento; se asumió filtrante simple. | D14: 420764.71 / 2044960.23
A15: IMB-242 | B15: 233 | C15: Misma coordenada que IMB-243: posible registro duplicado. | D15: 420762.20 / 2045251.06
A16: IMB-243 | B16: 232 | C16: Misma coordenada que IMB-242: posible registro duplicado. | D16: 420762.20 / 2045251.05
A17: IMB-445B | B17: 30 | C17: Número 445 repetido en el levantamiento; se asignó IMB-445B. | D17: 420507.14 / 2046520.69
... A19: IMB-460 | B19: 14 | C19: El punto queda fuera de los lotes del Master Plan; verificar si pertenece a CJB o si la coordenada es correcta. | D19: 420680.44 / 2046402.58

Sheet Metodología
A1: Cómo se construyó el inventario
A2: Georreferencia del Master Plan y ubicación de cada imbornal
A5: Fuente de los puntos | B5: Levantamiento de imbornales de Verasol del 27/07/2026 (coordenadas Norte, Este y cota).
A6: Sistema de coordenadas | B6: WGS 84 / UTM zona 19N (EPSG:32619)
A7: Master Plan | B7: SVG del sistema de mapas (MAPA NUEVO - CJB/assets/mapa.svg). No se contó con el plano de AutoCAD, por lo que el SVG se georreferenció por calibración.
A8: Calibración | B8: Escala 4.3184 m por unidad del SVG, rotación 0.00013°. Fórmula: E = E0 + s·x ; N = N0 − s·y (x, y en unidades del SVG). La escala coincide con la obtenida comparando las áreas de los lotes del SVG con las áreas registradas en la base de datos.
A9: Verificación | B9: Superposición sobre la imagen satelital de Esri (World Imagery): los bordes de los lotes coinciden con las manzanas reales con una precisión de 1–2 m en zonas urbanizadas.
A10: Ubicación de cada punto | B10: «Calle»: el punto cae en un lote vial del Master Plan (15-01-xx), cuyo nombre es la calle. «Dentro de lote»: cae dentro de un lote no vial. «Lote más cercano»: el lote no vial más próximo y su distancia.
A11: Alcance | B11: El levantamiento cubre los imbornales de calles y áreas públicas; no incluye los filtrantes internos de residenciales y plazas comerciales.
A12: Actualización | B12: Ejecutar tools/generar_activos_cjb.py con el nuevo levantamiento: regenera esta hoja y la capa del mapa (MAPA NUEVO - CJB/data/activos_cjb.json).
